Workbook

Sheet Summary
A1: Particulars | B1: Jan Budget | C1: Jan Actual | D1: Feb Budget | E1: Feb Actual | F1: Mar Budget | G1: Mar Actual | H1: Apr Budget | I1: Apr Actual | J1: May Budget | K1: May Actual | L1: Jun Budget | M1: Jun Actual | N1: Jul Budget | O1: Jul Actual | P1: Aug Budget | Q1: Aug Actual | R1: Sep Budget | S1: Sep Actual | T1: Oct Budget | U1: Oct Actual | V1: Nov Budget | W1: Nov Actual | X1: Dec Budget | Y1: Dec Actual | Z1: Annual Budget | AA1: Annual Actual
A2: Revenue | B2: =Chennai!B2+Mumbai!B2+Pune!B2+Hyderabad!B2+Bangalore!B2 -> 63000000 | C2: =Chennai!C2+Mumbai!C2+Pune!C2+Hyderabad!C2+Bangalore!C2 -> 63000000 | D2: =Chennai!D2+Mumbai!D2+Pune!D2+Hyderabad!D2+Bangalore!D2 -> 64260000 | E2: =Chennai!E2+Mumbai!E2+Pune!E2+Hyderabad!E2+Bangalore!E2 -> 65545200 | F2: =Chennai!F2+Mumbai!F2+Pune!F2+Hyderabad!F2+Bangalore!F2 -> 65520000 | G2: =Chennai!G2+Mumbai!G2+Pune!G2+Hyderabad!G2+Bangalore!G2 -> 62899200 | H2: =Chennai!H2+Mumbai!H2+Pune!H2+Hyderabad!H2+Bangalore!H2 -> 64890000 | I2: =Chennai!I2+Mumbai!I2+Pune!I2+Hyderabad!I2+Bangalore!I2 -> 66836700 | ... AA2: =Chennai!AA2+Mumbai!AA2+Pune!AA2+Hyderabad!AA2+Bangalore!AA2 -> 831335400
A3: COGS | B3: =Chennai!B3+Mumbai!B3+Pune!B3+Hyderabad!B3+Bangalore!B3 -> 37800000 | C3: =Chennai!C3+Mumbai!C3+Pune!C3+Hyderabad!C3+Bangalore!C3 -> 38115000 | D3: =Chennai!D3+Mumbai!D3+Pune!D3+Hyderabad!D3+Bangalore!D3 -> 38556000 | E3: =Chennai!E3+Mumbai!E3+Pune!E3+Hyderabad!E3+Bangalore!E3 -> 39654846 | F3: =Chennai!F3+Mumbai!F3+Pune!F3+Hyderabad!F3+Bangalore!F3 -> 39312000 | G3: =Chennai!G3+Mumbai!G3+Pune!G3+Hyderabad!G3+Bangalore!G3 -> 38054016 | H3: =Chennai!H3+Mumbai!H3+Pune!H3+Hyderabad!H3+Bangalore!H3 -> 38934000 | I3: =Chennai!I3+Mumbai!I3+Pune!I3+Hyderabad!I3+Bangalore!I3 -> 40436204 | ... AA3: =Chennai!AA3+Mumbai!AA3+Pune!AA3+Hyderabad!AA3+Bangalore!AA3 -> 502957918
A4: Gross Profit | B4: =B2-B3 -> 25200000 | C4: =C2-C3 -> 24885000 | D4: =D2-D3 -> 25704000 | E4: =E2-E3 -> 25890354 | F4: =F2-F3 -> 26208000 | G4: =G2-G3 -> 24845184 | H4: =H2-H3 -> 25956000 | I4: =I2-I3 -> 26400496 | ... AA4: =AA2-AA3 -> 328377482
A5: Salaries | B5: =Chennai!B5+Mumbai!B5+Pune!B5+Hyderabad!B5+Bangalore!B5 -> 7560000 | C5: =Chennai!C5+Mumbai!C5+Pune!C5+Hyderabad!C5+Bangalore!C5 -> 7711200 | D5: =Chennai!D5+Mumbai!D5+Pune!D5+Hyderabad!D5+Bangalore!D5 -> 7711200 | E5: =Chennai!E5+Mumbai!E5+Pune!E5+Hyderabad!E5+Bangalore!E5 -> 7865424 | F5: =Chennai!F5+Mumbai!F5+Pune!F5+Hyderabad!F5+Bangalore!F5 -> 7862400 | G5: =Chennai!G5+Mumbai!G5+Pune!G5+Hyderabad!G5+Bangalore!G5 -> 8019648 | H5: =Chennai!H5+Mumbai!H5+Pune!H5+Hyderabad!H5+Bangalore!H5 -> 7786800 | I5: =Chennai!I5+Mumbai!I5+Pune!I5+Hyderabad!I5+Bangalore!I5 -> 7942536 | ... AA5: =Chennai!AA5+Mumbai!AA5+Pune!AA5+Hyderabad!AA5+Bangalore!AA5 -> 101787840
A6: Rent | B6: =Chennai!B6+Mumbai!B6+Pune!B6+Hyderabad!B6+Bangalore!B6 -> 2500000 | C6: =Chennai!C6+Mumbai!C6+Pune!C6+Hyderabad!C6+Bangalore!C6 -> 2500000 | D6: =Chennai!D6+Mumbai!D6+Pune!D6+Hyderabad!D6+Bangalore!D6 -> 2500000 | E6: =Chennai!E6+Mumbai!E6+Pune!E6+Hyderabad!E6+Bangalore!E6 -> 2500000 | F6: =Chennai!F6+Mumbai!F6+Pune!F6+Hyderabad!F6+Bangalore!F6 -> 2500000 | G6: =Chennai!G6+Mumbai!G6+Pune!G6+Hyderabad!G6+Bangalore!G6 -> 2500000 | H6: =Chennai!H6+Mumbai!H6+Pune!H6+Hyderabad!H6+Bangalore!H6 -> 2500000 | I6: =Chennai!I6+Mumbai!I6+Pune!I6+Hyderabad!I6+Bangalore!I6 -> 2500000 | ... AA6: =Chennai!AA6+Mumbai!AA6+Pune!AA6+Hyderabad!AA6+Bangalore!AA6 -> 30000000
A7: Utilities | B7: =Chennai!B7+Mumbai!B7+Pune!B7+Hyderabad!B7+Bangalore!B7 -> 756000 | C7: =Chennai!C7+Mumbai!C7+Pune!C7+Hyderabad!C7+Bangalore!C7 -> 778680 | D7: =Chennai!D7+Mumbai!D7+Pune!D7+Hyderabad!D7+Bangalore!D7 -> 771120 | E7: =Chennai!E7+Mumbai!E7+Pune!E7+Hyderabad!E7+Bangalore!E7 -> 794253 | F7: =Chennai!F7+Mumbai!F7+Pune!F7+Hyderabad!F7+Bangalore!F7 -> 786240 | G7: =Chennai!G7+Mumbai!G7+Pune!G7+Hyderabad!G7+Bangalore!G7 -> 809827 | H7: =Chennai!H7+Mumbai!H7+Pune!H7+Hyderabad!H7+Bangalore!H7 -> 778680 | I7: =Chennai!I7+Mumbai!I7+Pune!I7+Hyderabad!I7+Bangalore!I7 -> 802041 | ... AA7: =Chennai!AA7+Mumbai!AA7+Pune!AA7+Hyderabad!AA7+Bangalore!AA7 -> 10278577
A8: Marketing | B8: =Chennai!B8+Mumbai!B8+Pune!B8+Hyderabad!B8+Bangalore!B8 -> 2520000 | C8: =Chennai!C8+Mumbai!C8+Pune!C8+Hyderabad!C8+Bangalore!C8 -> 2646000 | D8: =Chennai!D8+Mumbai!D8+Pune!D8+Hyderabad!D8+Bangalore!D8 -> 2570400 | E8: =Chennai!E8+Mumbai!E8+Pune!E8+Hyderabad!E8+Bangalore!E8 -> 2698920 | F8: =Chennai!F8+Mumbai!F8+Pune!F8+Hyderabad!F8+Bangalore!F8 -> 2620800 | G8: =Chennai!G8+Mumbai!G8+Pune!G8+Hyderabad!G8+Bangalore!G8 -> 2751840 | H8: =Chennai!H8+Mumbai!H8+Pune!H8+Hyderabad!H8+Bangalore!H8 -> 2595600 | I8: =Chennai!I8+Mumbai!I8+Pune!I8+Hyderabad!I8+Bangalore!I8 -> 2725380 | ... AA8: =Chennai!AA8+Mumbai!AA8+Pune!AA8+Hyderabad!AA8+Bangalore!AA8 -> 34927200
A9: Other Opex | B9: =Chennai!B9+Mumbai!B9+Pune!B9+Hyderabad!B9+Bangalore!B9 -> 1575000 | C9: =Chennai!C9+Mumbai!C9+Pune!C9+Hyderabad!C9+Bangalore!C9 -> 1622250 | D9: =Chennai!D9+Mumbai!D9+Pune!D9+Hyderabad!D9+Bangalore!D9 -> 1606500 | E9: =Chennai!E9+Mumbai!E9+Pune!E9+Hyderabad!E9+Bangalore!E9 -> 1654695 | F9: =Chennai!F9+Mumbai!F9+Pune!F9+Hyderabad!F9+Bangalore!F9 -> 1638000 | G9: =Chennai!G9+Mumbai!G9+Pune!G9+Hyderabad!G9+Bangalore!G9 -> 1687140 | H9: =Chennai!H9+Mumbai!H9+Pune!H9+Hyderabad!H9+Bangalore!H9 -> 1622250 | I9: =Chennai!I9+Mumbai!I9+Pune!I9+Hyderabad!I9+Bangalore!I9 -> 1670918 | ... AA9: =Chennai!AA9+Mumbai!AA9+Pune!AA9+Hyderabad!AA9+Bangalore!AA9 -> 21413701
A10: EBITDA | B10: =B4-SUM(B5:B9) -> 10289000 | C10: =C4-SUM(C5:C9) -> 9626870 | D10: =D4-SUM(D5:D9) -> 10544780 | E10: =E4-SUM(E5:E9) -> 10377062 | F10: =F4-SUM(F5:F9) -> 10800560 | G10: =G4-SUM(G5:G9) -> 9076729 | H10: =H4-SUM(H5:H9) -> 10672670 | I10: =I4-SUM(I5:I9) -> 10759621 | ... AA10: =AA4-SUM(AA5:AA9) -> 129970164
A11: Depreciation | B11: =Chennai!B11+Mumbai!B11+Pune!B11+Hyderabad!B11+Bangalore!B11 -> 1250000 | C11: =Chennai!C11+Mumbai!C11+Pune!C11+Hyderabad!C11+Bangalore!C11 -> 1250000 | D11: =Chennai!D11+Mumbai!D11+Pune!D11+Hyderabad!D11+Bangalore!D11 -> 1250000 | E11: =Chennai!E11+Mumbai!E11+Pune!E11+Hyderabad!E11+Bangalore!E11 -> 1250000 | F11: =Chennai!F11+Mumbai!F11+Pune!F11+Hyderabad!F11+Bangalore!F11 -> 1250000 | G11: =Chennai!G11+Mumbai!G11+Pune!G11+Hyderabad!G11+Bangalore!G11 -> 1250000 | H11: =Chennai!H11+Mumbai!H11+Pune!H11+Hyderabad!H11+Bangalore!H11 -> 1250000 | I11: =Chennai!I11+Mumbai!I11+Pune!I11+Hyderabad!I11+Bangalore!I11 -> 1250000 | ... AA11: =Chennai!AA11+Mumbai!AA11+Pune!AA11+Hyderabad!AA11+Bangalore!AA11 -> 15000000
A12: Interest | B12: =Chennai!B12+Mumbai!B12+Pune!B12+Hyderabad!B12+Bangalore!B12 -> 500000 | C12: =Chennai!C12+Mumbai!C12+Pune!C12+Hyderabad!C12+Bangalore!C12 -> 500000 | D12: =Chennai!D12+Mumbai!D12+Pune!D12+Hyderabad!D12+Bangalore!D12 -> 500000 | E12: =Chennai!E12+Mumbai!E12+Pune!E12+Hyderabad!E12+Bangalore!E12 -> 500000 | F12: =Chennai!F12+Mumbai!F12+Pune!F12+Hyderabad!F12+Bangalore!F12 -> 500000 | G12: =Chennai!G12+Mumbai!G12+Pune!G12+Hyderabad!G12+Bangalore!G12 -> 500000 | H12: =Chennai!H12+Mumbai!H12+Pune!H12+Hyderabad!H12+Bangalore!H12 -> 500000 | I12: =Chennai!I12+Mumbai!I12+Pune!I12+Hyderabad!I12+Bangalore!I12 -> 500000 | ... AA12: =Chennai!AA12+Mumbai!AA12+Pune!AA12+Hyderabad!AA12+Bangalore!AA12 -> 6000000
A13: Profit Before Tax | B13: =B10-B11-B12 -> 8539000 | C13: =C10-C11-C12 -> 7876870 | D13: =D10-D11-D12 -> 8794780 | E13: =E10-E11-E12 -> 8627062 | F13: =F10-F11-F12 -> 9050560 | G13: =G10-G11-G12 -> 7326729 | H13: =H10-H11-H12 -> 8922670 | I13: =I10-I11-I12 -> 9009621 | ... AA13: =AA10-AA11-AA12 -> 108970164
A14: Tax | B14: =Chennai!B14+Mumbai!B14+Pune!B14+Hyderabad!B14+Bangalore!B14 -> 2134750 | C14: =Chennai!C14+Mumbai!C14+Pune!C14+Hyderabad!C14+Bangalore!C14 -> 1969218 | D14: =Chennai!D14+Mumbai!D14+Pune!D14+Hyderabad!D14+Bangalore!D14 -> 2198695 | E14: =Chennai!E14+Mumbai!E14+Pune!E14+Hyderabad!E14+Bangalore!E14 -> 2156765 | F14: =Chennai!F14+Mumbai!F14+Pune!F14+Hyderabad!F14+Bangalore!F14 -> 2262640 | G14: =Chennai!G14+Mumbai!G14+Pune!G14+Hyderabad!G14+Bangalore!G14 -> 1831682 | H14: =Chennai!H14+Mumbai!H14+Pune!H14+Hyderabad!H14+Bangalore!H14 -> 2230668 | I14: =Chennai!I14+Mumbai!I14+Pune!I14+Hyderabad!I14+Bangalore!I14 -> 2252405 | ... AA14: =Chennai!AA14+Mumbai!AA14+Pune!AA14+Hyderabad!AA14+Bangalore!AA14 -> 27242541
A15: Net Profit | B15: =B13-B14 -> 6404250 | C15: =C13-C14 -> 5907652 | D15: =D13-D14 -> 6596085 | E15: =E13-E14 -> 6470297 | F15: =F13-F14 -> 6787920 | G15: =G13-G14 -> 5495047 | H15: =H13-H14 -> 6692002 | I15: =I13-I14 -> 6757216 | ... AA15: =AA13-AA14 -> 81727623

Sheet Variance Analysis
A1: Retail Group — Budget vs Actual Variance Analysis (FY)
A2: Prepared for: Group CFO | Prepared by: Financial Analyst | All figures in ₹
A4: 1. Consolidated P&L — Budget vs Actual
A5: Particulars | B5: Annual Budget | C5: Annual Actual | D5: Variance (₹) | E5: Variance % | F5: Nature | G5: Status
A6: Revenue | B6: =Summary!Z2 -> 831600000 | C6: =Summary!AA2 -> 831335400 | D6: =C6-B6 -> -264600 | E6: =D6/B6 -> -0.00031818182 | F6: Income | G6: =IF(F6="Cost",IF(D6<=0,"Favourable","Unfavourable"),IF(D6>=0,"Favourable","Unfavourable")) -> Unfavourable
A7: COGS | B7: =Summary!Z3 -> 498960000 | C7: =Summary!AA3 -> 502957918 | D7: =C7-B7 -> 3997918 | E7: =D7/B7 -> 0.008012502 | F7: Cost | G7: =IF(F7="Cost",IF(D7<=0,"Favourable","Unfavourable"),IF(D7>=0,"Favourable","Unfavourable")) -> Unfavourable
A8: Gross Profit | B8: =Summary!Z4 -> 332640000 | C8: =Summary!AA4 -> 328377482 | D8: =C8-B8 -> -4262518 | E8: =D8/B8 -> -0.012814208 | F8: Income | G8: =IF(F8="Cost",IF(D8<=0,"Favourable","Unfavourable"),IF(D8>=0,"Favourable","Unfavourable")) -> Unfavourable
A9: Salaries | B9: =Summary!Z5 -> 99792000 | C9: =Summary!AA5 -> 101787840 | D9: =C9-B9 -> 1995840 | E9: =D9/B9 -> 0.02 | F9: Cost | G9: =IF(F9="Cost",IF(D9<=0,"Favourable","Unfavourable"),IF(D9>=0,"Favourable","Unfavourable")) -> Unfavourable
A10: Rent | B10: =Summary!Z6 -> 30000000 | C10: =Summary!AA6 -> 30000000 | D10: =C10-B10 -> 0 | E10: =D10/B10 -> 0 | F10: Cost | G10: =IF(F10="Cost",IF(D10<=0,"Favourable","Unfavourable"),IF(D10>=0,"Favourable","Unfavourable")) -> Favourable
A11: Utilities | B11: =Summary!Z7 -> 9979200 | C11: =Summary!AA7 -> 10278577 | D11: =C11-B11 -> 299377 | E11: =D11/B11 -> 0.0300001 | F11: Cost | G11: =IF(F11="Cost",IF(D11<=0,"Favourable","Unfavourable"),IF(D11>=0,"Favourable","Unfavourable")) -> Unfavourable
A12: Marketing | B12: =Summary!Z8 -> 33264000 | C12: =Summary!AA8 -> 34927200 | D12: =C12-B12 -> 1663200 | E12: =D12/B12 -> 0.05 | F12: Cost | G12: =IF(F12="Cost",IF(D12<=0,"Favourable","Unfavourable"),IF(D12>=0,"Favourable","Unfavourable")) -> Unfavourable
A13: Other Opex | B13: =Summary!Z9 -> 20790000 | C13: =Summary!AA9 -> 21413701 | D13: =C13-B13 -> 623701 | E13: =D13/B13 -> 0.030000048 | F13: Cost | G13: =IF(F13="Cost",IF(D13<=0,"Favourable","Unfavourable"),IF(D13>=0,"Favourable","Unfavourable")) -> Unfavourable
A14: EBITDA | B14: =Summary!Z10 -> 138814800 | C14: =Summary!AA10 -> 129970164 | D14: =C14-B14 -> -8844636 | E14: =D14/B14 -> -0.063715368 | F14: Income | G14: =IF(F14="Cost",IF(D14<=0,"Favourable","Unfavourable"),IF(D14>=0,"Favourable","Unfavourable")) -> Unfavourable
A15: Depreciation | B15: =Summary!Z11 -> 15000000 | C15: =Summary!AA11 -> 15000000 | D15: =C15-B15 -> 0 | E15: =D15/B15 -> 0 | F15: Cost | G15: =IF(F15="Cost",IF(D15<=0,"Favourable","Unfavourable"),IF(D15>=0,"Favourable","Unfavourable")) -> Favourable
A16: Interest | B16: =Summary!Z12 -> 6000000 | C16: =Summary!AA12 -> 6000000 | D16: =C16-B16 -> 0 | E16: =D16/B16 -> 0 | F16: Cost | G16: =IF(F16="Cost",IF(D16<=0,"Favourable","Unfavourable"),IF(D16>=0,"Favourable","Unfavourable")) -> Favourable
A17: Profit Before Tax | B17: =Summary!Z13 -> 117814800 | C17: =Summary!AA13 -> 108970164 | D17: =C17-B17 -> -8844636 | E17: =D17/B17 -> -0.075072368 | F17: Income | G17: =IF(F17="Cost",IF(D17<=0,"Favourable","Unfavourable"),IF(D17>=0,"Favourable","Unfavourable")) -> Unfavourable
... A19: Net Profit | B19: =Summary!Z15 -> 88361099 | C19: =Summary!AA15 -> 81727623 | D19: =C19-B19 -> -6633476 | E19: =D19/B19 -> -0.075072357 | F19: Income | G19: =IF(F19="Cost",IF(D19<=0,"Favourable","Unfavourable"),IF(D19>=0,"Favourable","Unfavourable")) -> Unfavourable
A22: 2. Net Profit by Branch — Budget vs Actual
A23: Branch | B23: Budget NP | C23: Actual NP | D23: Variance (₹) | E23: Variance %
A24: Chennai | B24: =Chennai!Z15 -> 17471251 | C24: =Chennai!AA15 -> 16155086 | D24: =C24-B24 -> -1316165 | E24: =D24/B24 -> -0.075333186
A25: Mumbai | B25: =Mumbai!Z15 -> 23500349 | C25: =Mumbai!AA15 -> 21868305 | D25: =C25-B25 -> -1632044 | E25: =D25/B25 -> -0.069447649
A26: Pune | B26: =Pune!Z15 -> 11442149 | C26: =Pune!AA15 -> 10441862 | D26: =C26-B26 -> -1000287 | E26: =D26/B26 -> -0.087421253
A27: Hyderabad | B27: =Hyderabad!Z15 -> 14456699 | C27: =Hyderabad!AA15 -> 13298470 | D27: =C27-B27 -> -1158229 | E27: =D27/B27 -> -0.080117114
A28: Bangalore | B28: =Bangalore!Z15 -> 21490651 | C28: =Bangalore!AA15 -> 19963900 | D28: =C28-B28 -> -1526751 | E28: =D28/B28 -> -0.071042566
A29: Group Total | B29: =SUM(B24:B28) -> 88361099 | C29: =SUM(C24:C28) -> 81727623 | D29: =C29-B29 -> -6633476 | E29: =D29/B29 -> -0.075072357
A32: 3. Revenue by Branch — Budget vs Actual
A33: Branch | B33: Budget Rev | C33: Actual Rev | D33: Variance (₹) | E33: Variance %
A34: Chennai | B34: =Chennai!Z2 -> 165000000 | C34: =Chennai!AA2 -> 164947500 | D34: =C34-B34 -> -52500 | E34: =D34/B34 -> -0.00031818182
A35: Mumbai | B35: =Mumbai!Z2 -> 204600000 | C35: =Mumbai!AA2 -> 204534900 | D35: =C35-B35 -> -65100 | E35: =D35/B35 -> -0.00031818182
A36: Pune | B36: =Pune!Z2 -> 125400000 | C36: =Pune!AA2 -> 125360100 | D36: =C36-B36 -> -39900 | E36: =D36/B36 -> -0.00031818182
A37: Hyderabad | B37: =Hyderabad!Z2 -> 145200000 | C37: =Hyderabad!AA2 -> 145153800 | D37: =C37-B37 -> -46200 | E37: =D37/B37 -> -0.00031818182
A38: Bangalore | B38: =Bangalore!Z2 -> 191400000 | C38: =Bangalore!AA2 -> 191339100 | D38: =C38-B38 -> -60900 | E38: =D38/B38 -> -0.00031818182
A39: Group Total | B39: =SUM(B34:B38) -> 831600000 | C39: =SUM(C34:C38) -> 831335400 | D39: =C39-B39 -> -264600 | E39: =D39/B39 -> -0.00031818182
A42: 4. Monthly Group Net Profit — Budget vs Actual
A43: Month | B43: Budget NP | C43: Actual NP | D43: Variance %
A44: Jan | B44: =Summary!B15 -> 6404250 | C44: =Summary!C15 -> 5907652 | D44: =C44/B44-1 -> -0.077541945
A45: Feb | B45: =Summary!D15 -> 6596085 | C45: =Summary!E15 -> 6470297 | D45: =C45/B45-1 -> -0.0190701
A46: Mar | B46: =Summary!F15 -> 6787920 | C46: =Summary!G15 -> 5495047 | D46: =C46/B46-1 -> -0.19046674
A47: Apr | B47: =Summary!H15 -> 6692002 | C47: =Summary!I15 -> 6757216 | D47: =C47/B47-1 -> 0.0097450658
A48: May | B48: =Summary!J15 -> 6979755 | C48: =Summary!K15 -> 6057689 | D48: =C48/B48-1 -> -0.13210578
...

Sheet Chennai
A1: Particulars | B1: Jan Budget | C1: Jan Actual | D1: Feb Budget | E1: Feb Actual | F1: Mar Budget | G1: Mar Actual | H1: Apr Budget | I1: Apr Actual | J1: May Budget | K1: May Actual | L1: Jun Budget | M1: Jun Actual | N1: Jul Budget | O1: Jul Actual | P1: Aug Budget | Q1: Aug Actual | R1: Sep Budget | S1: Sep Actual | T1: Oct Budget | U1: Oct Actual | V1: Nov Budget | W1: Nov Actual | X1: Dec Budget | Y1: Dec Actual | Z1: Annual Budget | AA1: Annual Actual
A2: Revenue | B2: 12500000 | C2: 12500000 | D2: 12750000 | E2: 13005000 | F2: 13000000 | G2: 12480000 | H2: 12875000 | I2: 13261250 | J2: 13250000 | K2: 12985000 | L2: 13500000 | M2: 13500000 | N2: 13750000 | O2: 14025000 | P2: 14000000 | Q2: 13440000 | R2: 13875000 | S2: 14291250 | T2: 14500000 | U2: 14500000 | V2: 15000000 | W2: 15600000 | X2: 16000000 | Y2: 15360000 | Z2: 165000000 | AA2: 164947500
A3: COGS | B3: 7500000 | C3: 7562500 | D3: 7650000 | E3: 7868025 | F3: 7800000 | G3: 7550400 | H3: 7725000 | I3: 8023056 | J3: 7950000 | K3: 7855925 | L3: 8100000 | M3: 8167500 | N3: 8250000 | O3: 8485125 | P3: 8400000 | Q3: 8131200 | R3: 8325000 | S3: 8646206 | T3: 8700000 | U3: 8772500 | V3: 9000000 | W3: 9438000 | X3: 9600000 | Y3: 9292800 | Z3: 99000000 | AA3: 99793237
A4: Gross Profit | B4: 5000000 | C4: 4937500 | D4: 5100000 | E4: 5136975 | F4: 5200000 | G4: 4929600 | H4: 5150000 | I4: 5238194 | J4: 5300000 | K4: 5129075 | L4: 5400000 | M4: 5332500 | N4: 5500000 | O4: 5539875 | P4: 5600000 | Q4: 5308800 | R4: 5550000 | S4: 5645044 | T4: 5800000 | U4: 5727500 | V4: 6000000 | W4: 6162000 | X4: 6400000 | Y4: 6067200 | Z4: 66000000 | AA4: 65154263
A5: Salaries | B5: 1500000 | C5: 1530000 | D5: 1530000 | E5: 1560600 | F5: 1560000 | G5: 1591200 | H5: 1545000 | I5: 1575900 | J5: 1590000 | K5: 1621800 | L5: 1620000 | M5: 1652400 | N5: 1650000 | O5: 1683000 | P5: 1680000 | Q5: 1713600 | R5: 1665000 | S5: 1698300 | T5: 1740000 | U5: 1774800 | V5: 1800000 | W5: 1836000 | X5: 1920000 | Y5: 1958400 | Z5: 19800000 | AA5: 20196000
A6: Rent | B6: 500000 | C6: 500000 | D6: 500000 | E6: 500000 | F6: 500000 | G6: 500000 | H6: 500000 | I6: 500000 | J6: 500000 | K6: 500000 | L6: 500000 | M6: 500000 | N6: 500000 | O6: 500000 | P6: 500000 | Q6: 500000 | R6: 500000 | S6: 500000 | T6: 500000 | U6: 500000 | V6: 500000 | W6: 500000 | X6: 500000 | Y6: 500000 | Z6: 6000000 | AA6: 6000000
A7: Utilities | B7: 150000 | C7: 154500 | D7: 153000 | E7: 157590 | F7: 156000 | G7: 160680 | H7: 154500 | I7: 159135 | J7: 159000 | K7: 163770 | L7: 162000 | M7: 166860 | N7: 165000 | O7: 169950 | P7: 168000 | Q7: 173040 | R7: 166500 | S7: 171495 | T7: 174000 | U7: 179220 | V7: 180000 | W7: 185400 | X7: 192000 | Y7: 197760 | Z7: 1980000 | AA7: 2039400
A8: Marketing | B8: 500000 | C8: 525000 | D8: 510000 | E8: 535500 | F8: 520000 | G8: 546000 | H8: 515000 | I8: 540750 | J8: 530000 | K8: 556500 | L8: 540000 | M8: 567000 | N8: 550000 | O8: 577500 | P8: 560000 | Q8: 588000 | R8: 555000 | S8: 582750 | T8: 580000 | U8: 609000 | V8: 600000 | W8: 630000 | X8: 640000 | Y8: 672000 | Z8: 6600000 | AA8: 6930000
A9: Other Opex | B9: 312500 | C9: 321875 | D9: 318750 | E9: 328312 | F9: 325000 | G9: 334750 | H9: 321875 | I9: 331531 | J9: 331250 | K9: 341188 | L9: 337500 | M9: 347625 | N9: 343750 | O9: 354062 | P9: 350000 | Q9: 360500 | R9: 346875 | S9: 357281 | T9: 362500 | U9: 373375 | V9: 375000 | W9: 386250 | X9: 400000 | Y9: 412000 | Z9: 4125000 | AA9: 4248749
A10: EBITDA | B10: 2037500 | C10: 1906125 | D10: 2088250 | E10: 2054973 | F10: 2139000 | G10: 1796970 | H10: 2113625 | I10: 2130878 | J10: 2189750 | K10: 1945817 | L10: 2240500 | M10: 2098615 | N10: 2291250 | O10: 2255363 | P10: 2342000 | Q10: 1973660 | R10: 2316625 | S10: 2335218 | T10: 2443500 | U10: 2291105 | V10: 2545000 | W10: 2624350 | X10: 2748000 | Y10: 2327040 | Z10: 27495000 | AA10: 25740114
A11: Depreciation | B11: 250000 | C11: 250000 | D11: 250000 | E11: 250000 | F11: 250000 | G11: 250000 | H11: 250000 | I11: 250000 | J11: 250000 | K11: 250000 | L11: 250000 | M11: 250000 | N11: 250000 | O11: 250000 | P11: 250000 | Q11: 250000 | R11: 250000 | S11: 250000 | T11: 250000 | U11: 250000 | V11: 250000 | W11: 250000 | X11: 250000 | Y11: 250000 | Z11: 3000000 | AA11: 3000000
A12: Interest | B12: 100000 | C12: 100000 | D12: 100000 | E12: 100000 | F12: 100000 | G12: 100000 | H12: 100000 | I12: 100000 | J12: 100000 | K12: 100000 | L12: 100000 | M12: 100000 | N12: 100000 | O12: 100000 | P12: 100000 | Q12: 100000 | R12: 100000 | S12: 100000 | T12: 100000 | U12: 100000 | V12: 100000 | W12: 100000 | X12: 100000 | Y12: 100000 | Z12: 1200000 | AA12: 1200000
A13: Profit Before Tax | B13: 1687500 | C13: 1556125 | D13: 1738250 | E13: 1704973 | F13: 1789000 | G13: 1446970 | H13: 1763625 | I13: 1780878 | J13: 1839750 | K13: 1595817 | L13: 1890500 | M13: 1748615 | N13: 1941250 | O13: 1905363 | P13: 1992000 | Q13: 1623660 | R13: 1966625 | S13: 1985218 | T13: 2093500 | U13: 1941105 | V13: 2195000 | W13: 2274350 | X13: 2398000 | Y13: 1977040 | Z13: 23295000 | AA13: 21540114
... A15: Net Profit | B15: 1265625 | C15: 1167094 | D15: 1303688 | E15: 1278730 | F15: 1341750 | G15: 1085228 | H15: 1322719 | I15: 1335658 | J15: 1379812 | K15: 1196863 | L15: 1417875 | M15: 1311461 | N15: 1455938 | O15: 1429022 | P15: 1494000 | Q15: 1217745 | R15: 1474969 | S15: 1488914 | T15: 1570125 | U15: 1455829 | V15: 1646250 | W15: 1705762 | X15: 1798500 | Y15: 1482780 | Z15: 17471251 | AA15: 16155086
B19: Generating floowking using AI
B20: Consolidated sheet
B21: Budget vs Actual variance sheet
B22: Variance % analysis
B23: YTD calculations
B24: Branch ranking
B25: Cash Flow statement
B26: Balance Sheet

Sheet Mumbai
A1: Particulars | B1: Jan Budget | C1: Jan Actual | D1: Feb Budget | E1: Feb Actual | F1: Mar Budget | G1: Mar Actual | H1: Apr Budget | I1: Apr Actual | J1: May Budget | K1: May Actual | L1: Jun Budget | M1: Jun Actual | N1: Jul Budget | O1: Jul Actual | P1: Aug Budget | Q1: Aug Actual | R1: Sep Budget | S1: Sep Actual | T1: Oct Budget | U1: Oct Actual | V1: Nov Budget | W1: Nov Actual | X1: Dec Budget | Y1: Dec Actual | Z1: Annual Budget | AA1: Annual Actual
A2: Revenue | B2: 15500000 | C2: 15500000 | D2: 15810000 | E2: 16126200 | F2: 16120000 | G2: 15475200 | H2: 15965000 | I2: 16443950 | J2: 16430000 | K2: 16101400 | L2: 16740000 | M2: 16740000 | N2: 17050000 | O2: 17391000 | P2: 17360000 | Q2: 16665600 | R2: 17205000 | S2: 17721150 | T2: 17980000 | U2: 17980000 | V2: 18600000 | W2: 19344000 | X2: 19840000 | Y2: 19046400 | Z2: 204600000 | AA2: 204534900
A3: COGS | B3: 9300000 | C3: 9377500 | D3: 9486000 | E3: 9756351 | F3: 9672000 | G3: 9362496 | H3: 9579000 | I3: 9948590 | J3: 9858000 | K3: 9741347 | L3: 10044000 | M3: 10127700 | N3: 10230000 | O3: 10521555 | P3: 10416000 | Q3: 10082688 | R3: 10323000 | S3: 10721296 | T3: 10788000 | U3: 10877900 | V3: 11160000 | W3: 11703120 | X3: 11904000 | Y3: 11523072 | Z3: 122760000 | AA3: 123743615
A4: Gross Profit | B4: 6200000 | C4: 6122500 | D4: 6324000 | E4: 6369849 | F4: 6448000 | G4: 6112704 | H4: 6386000 | I4: 6495360 | J4: 6572000 | K4: 6360053 | L4: 6696000 | M4: 6612300 | N4: 6820000 | O4: 6869445 | P4: 6944000 | Q4: 6582912 | R4: 6882000 | S4: 6999854 | T4: 7192000 | U4: 7102100 | V4: 7440000 | W4: 7640880 | X4: 7936000 | Y4: 7523328 | Z4: 81840000 | AA4: 80791285
A5: Salaries | B5: 1860000 | C5: 1897200 | D5: 1897200 | E5: 1935144 | F5: 1934400 | G5: 1973088 | H5: 1915800 | I5: 1954116 | J5: 1971600 | K5: 2011032 | L5: 2008800 | M5: 2048976 | N5: 2046000 | O5: 2086920 | P5: 2083200 | Q5: 2124864 | R5: 2064600 | S5: 2105892 | T5: 2157600 | U5: 2200752 | V5: 2232000 | W5: 2276640 | X5: 2380800 | Y5: 2428416 | Z5: 24552000 | AA5: 25043040
A6: Rent | B6: 500000 | C6: 500000 | D6: 500000 | E6: 500000 | F6: 500000 | G6: 500000 | H6: 500000 | I6: 500000 | J6: 500000 | K6: 500000 | L6: 500000 | M6: 500000 | N6: 500000 | O6: 500000 | P6: 500000 | Q6: 500000 | R6: 500000 | S6: 500000 | T6: 500000 | U6: 500000 | V6: 500000 | W6: 500000 | X6: 500000 | Y6: 500000 | Z6: 6000000 | AA6: 6000000
A7: Utilities | B7: 186000 | C7: 191580 | D7: 189720 | E7: 195412 | F7: 193440 | G7: 199243 | H7: 191580 | I7: 197327 | J7: 197160 | K7: 203075 | L7: 200880 | M7: 206906 | N7: 204600 | O7: 210738 | P7: 208320 | Q7: 214570 | R7: 206460 | S7: 212654 | T7: 215760 | U7: 222233 | V7: 223200 | W7: 229896 | X7: 238080 | Y7: 245222 | Z7: 2455200 | AA7: 2528856
A8: Marketing | B8: 620000 | C8: 651000 | D8: 632400 | E8: 664020 | F8: 644800 | G8: 677040 | H8: 638600 | I8: 670530 | J8: 657200 | K8: 690060 | L8: 669600 | M8: 703080 | N8: 682000 | O8: 716100 | P8: 694400 | Q8: 729120 | R8: 688200 | S8: 722610 | T8: 719200 | U8: 755160 | V8: 744000 | W8: 781200 | X8: 793600 | Y8: 833280 | Z8: 8184000 | AA8: 8593200
A9: Other Opex | B9: 387500 | C9: 399125 | D9: 395250 | E9: 407108 | F9: 403000 | G9: 415090 | H9: 399125 | I9: 411099 | J9: 410750 | K9: 423072 | L9: 418500 | M9: 431055 | N9: 426250 | O9: 439038 | P9: 434000 | Q9: 447020 | R9: 430125 | S9: 443029 | T9: 449500 | U9: 462985 | V9: 465000 | W9: 478950 | X9: 496000 | Y9: 510880 | Z9: 5115000 | AA9: 5268451
A10: EBITDA | B10: 2646500 | C10: 2483595 | D10: 2709430 | E10: 2668165 | F10: 2772360 | G10: 2348243 | H10: 2740895 | I10: 2762288 | J10: 2835290 | K10: 2532814 | L10: 2898220 | M10: 2722283 | N10: 2961150 | O10: 2916649 | P10: 3024080 | Q10: 2567338 | R10: 2992615 | S10: 3015669 | T10: 3149940 | U10: 2960970 | V10: 3275800 | W10: 3374194 | X10: 3527520 | Y10: 3005530 | Z10: 35533800 | AA10: 33357738
A11: Depreciation | B11: 250000 | C11: 250000 | D11: 250000 | E11: 250000 | F11: 250000 | G11: 250000 | H11: 250000 | I11: 250000 | J11: 250000 | K11: 250000 | L11: 250000 | M11: 250000 | N11: 250000 | O11: 250000 | P11: 250000 | Q11: 250000 | R11: 250000 | S11: 250000 | T11: 250000 | U11: 250000 | V11: 250000 | W11: 250000 | X11: 250000 | Y11: 250000 | Z11: 3000000 | AA11: 3000000
A12: Interest | B12: 100000 | C12: 100000 | D12: 100000 | E12: 100000 | F12: 100000 | G12: 100000 | H12: 100000 | I12: 100000 | J12: 100000 | K12: 100000 | L12: 100000 | M12: 100000 | N12: 100000 | O12: 100000 | P12: 100000 | Q12: 100000 | R12: 100000 | S12: 100000 | T12: 100000 | U12: 100000 | V12: 100000 | W12: 100000 | X12: 100000 | Y12: 100000 | Z12: 1200000 | AA12: 1200000
A13: Profit Before Tax | B13: 2296500 | C13: 2133595 | D13: 2359430 | E13: 2318165 | F13: 2422360 | G13: 1998243 | H13: 2390895 | I13: 2412288 | J13: 2485290 | K13: 2182814 | L13: 2548220 | M13: 2372283 | N13: 2611150 | O13: 2566649 | P13: 2674080 | Q13: 2217338 | R13: 2642615 | S13: 2665669 | T13: 2799940 | U13: 2610970 | V13: 2925800 | W13: 3024194 | X13: 3177520 | Y13: 2655530 | Z13: 31333800 | AA13: 29157738
... A15: Net Profit | B15: 1722375 | C15: 1600196 | D15: 1769572 | E15: 1738624 | F15: 1816770 | G15: 1498682 | H15: 1793171 | I15: 1809216 | J15: 1863968 | K15: 1637110 | L15: 1911165 | M15: 1779212 | N15: 1958362 | O15: 1924987 | P15: 2005560 | Q15: 1663004 | R15: 1981961 | S15: 1999252 | T15: 2099955 | U15: 1958228 | V15: 2194350 | W15: 2268146 | X15: 2383140 | Y15: 1991648 | Z15: 23500349 | AA15: 21868305

Sheet Pune
A1: Particulars | B1: Jan Budget | C1: Jan Actual | D1: Feb Budget | E1: Feb Actual | F1: Mar Budget | G1: Mar Actual | H1: Apr Budget | I1: Apr Actual | J1: May Budget | K1: May Actual | L1: Jun Budget | M1: Jun Actual | N1: Jul Budget | O1: Jul Actual | P1: Aug Budget | Q1: Aug Actual | R1: Sep Budget | S1: Sep Actual | T1: Oct Budget | U1: Oct Actual | V1: Nov Budget | W1: Nov Actual | X1: Dec Budget | Y1: Dec Actual | Z1: Annual Budget | AA1: Annual Actual
A2: Revenue | B2: 9500000 | C2: 9500000 | D2: 9690000 | E2: 9883800 | F2: 9880000 | G2: 9484800 | H2: 9785000 | I2: 10078550 | J2: 10070000 | K2: 9868600 | L2: 10260000 | M2: 10260000 | N2: 10450000 | O2: 10659000 | P2: 10640000 | Q2: 10214400 | R2: 10545000 | S2: 10861350 | T2: 11020000 | U2: 11020000 | V2: 11400000 | W2: 11856000 | X2: 12160000 | Y2: 11673600 | Z2: 125400000 | AA2: 125360100
A3: COGS | B3: 5700000 | C3: 5747500 | D3: 5814000 | E3: 5979699 | F3: 5928000 | G3: 5738304 | H3: 5871000 | I3: 6097523 | J3: 6042000 | K3: 5970503 | L3: 6156000 | M3: 6207300 | N3: 6270000 | O3: 6448695 | P3: 6384000 | Q3: 6179712 | R3: 6327000 | S3: 6571117 | T3: 6612000 | U3: 6667100 | V3: 6840000 | W3: 7172880 | X3: 7296000 | Y3: 7062528 | Z3: 75240000 | AA3: 75842861
A4: Gross Profit | B4: 3800000 | C4: 3752500 | D4: 3876000 | E4: 3904101 | F4: 3952000 | G4: 3746496 | H4: 3914000 | I4: 3981027 | J4: 4028000 | K4: 3898097 | L4: 4104000 | M4: 4052700 | N4: 4180000 | O4: 4210305 | P4: 4256000 | Q4: 4034688 | R4: 4218000 | S4: 4290233 | T4: 4408000 | U4: 4352900 | V4: 4560000 | W4: 4683120 | X4: 4864000 | Y4: 4611072 | Z4: 50160000 | AA4: 49517239
A5: Salaries | B5: 1140000 | C5: 1162800 | D5: 1162800 | E5: 1186056 | F5: 1185600 | G5: 1209312 | H5: 1174200 | I5: 1197684 | J5: 1208400 | K5: 1232568 | L5: 1231200 | M5: 1255824 | N5: 1254000 | O5: 1279080 | P5: 1276800 | Q5: 1302336 | R5: 1265400 | S5: 1290708 | T5: 1322400 | U5: 1348848 | V5: 1368000 | W5: 1395360 | X5: 1459200 | Y5: 1488384 | Z5: 15048000 | AA5: 15348960
A6: Rent | B6: 500000 | C6: 500000 | D6: 500000 | E6: 500000 | F6: 500000 | G6: 500000 | H6: 500000 | I6: 500000 | J6: 500000 | K6: 500000 | L6: 500000 | M6: 500000 | N6: 500000 | O6: 500000 | P6: 500000 | Q6: 500000 | R6: 500000 | S6: 500000 | T6: 500000 | U6: 500000 | V6: 500000 | W6: 500000 | X6: 500000 | Y6: 500000 | Z6: 6000000 | AA6: 6000000
A7: Utilities | B7: 114000 | C7: 117420 | D7: 116280 | E7: 119768 | F7: 118560 | G7: 122117 | H7: 117420 | I7: 120943 | J7: 120840 | K7: 124465 | L7: 123120 | M7: 126814 | N7: 125400 | O7: 129162 | P7: 127680 | Q7: 131510 | R7: 126540 | S7: 130336 | T7: 132240 | U7: 136207 | V7: 136800 | W7: 140904 | X7: 145920 | Y7: 150298 | Z7: 1504800 | AA7: 1549944
A8: Marketing | B8: 380000 | C8: 399000 | D8: 387600 | E8: 406980 | F8: 395200 | G8: 414960 | H8: 391400 | I8: 410970 | J8: 402800 | K8: 422940 | L8: 410400 | M8: 430920 | N8: 418000 | O8: 438900 | P8: 425600 | Q8: 446880 | R8: 421800 | S8: 442890 | T8: 440800 | U8: 462840 | V8: 456000 | W8: 478800 | X8: 486400 | Y8: 510720 | Z8: 5016000 | AA8: 5266800
A9: Other Opex | B9: 237500 | C9: 244625 | D9: 242250 | E9: 249518 | F9: 247000 | G9: 254410 | H9: 244625 | I9: 251964 | J9: 251750 | K9: 259302 | L9: 256500 | M9: 264195 | N9: 261250 | O9: 269088 | P9: 266000 | Q9: 273980 | R9: 263625 | S9: 271534 | T9: 275500 | U9: 283765 | V9: 285000 | W9: 293550 | X9: 304000 | Y9: 313120 | Z9: 3135000 | AA9: 3229051
A10: EBITDA | B10: 1428500 | C10: 1328655 | D10: 1467070 | E10: 1441779 | F10: 1505640 | G10: 1245697 | H10: 1486355 | I10: 1499466 | J10: 1544210 | K10: 1358822 | L10: 1582780 | M10: 1474947 | N10: 1621350 | O10: 1594075 | P10: 1659920 | Q10: 1379982 | R10: 1640635 | S10: 1654765 | T10: 1737060 | U10: 1621240 | V10: 1814200 | W10: 1874506 | X10: 1968480 | Y10: 1648550 | Z10: 19456200 | AA10: 18122484
A11: Depreciation | B11: 250000 | C11: 250000 | D11: 250000 | E11: 250000 | F11: 250000 | G11: 250000 | H11: 250000 | I11: 250000 | J11: 250000 | K11: 250000 | L11: 250000 | M11: 250000 | N11: 250000 | O11: 250000 | P11: 250000 | Q11: 250000 | R11: 250000 | S11: 250000 | T11: 250000 | U11: 250000 | V11: 250000 | W11: 250000 | X11: 250000 | Y11: 250000 | Z11: 3000000 | AA11: 3000000
A12: Interest | B12: 100000 | C12: 100000 | D12: 100000 | E12: 100000 | F12: 100000 | G12: 100000 | H12: 100000 | I12: 100000 | J12: 100000 | K12: 100000 | L12: 100000 | M12: 100000 | N12: 100000 | O12: 100000 | P12: 100000 | Q12: 100000 | R12: 100000 | S12: 100000 | T12: 100000 | U12: 100000 | V12: 100000 | W12: 100000 | X12: 100000 | Y12: 100000 | Z12: 1200000 | AA12: 1200000
A13: Profit Before Tax | B13: 1078500 | C13: 978655 | D13: 1117070 | E13: 1091779 | F13: 1155640 | G13: 895697 | H13: 1136355 | I13: 1149466 | J13: 1194210 | K13: 1008822 | L13: 1232780 | M13: 1124947 | N13: 1271350 | O13: 1244075 | P13: 1309920 | Q13: 1029982 | R13: 1290635 | S13: 1304765 | T13: 1387060 | U13: 1271240 | V13: 1464200 | W13: 1524506 | X13: 1618480 | Y13: 1298550 | Z13: 15256200 | AA13: 13922484
... A15: Net Profit | B15: 808875 | C15: 733991 | D15: 837802 | E15: 818834 | F15: 866730 | G15: 671773 | H15: 852266 | I15: 862100 | J15: 895658 | K15: 756616 | L15: 924585 | M15: 843710 | N15: 953512 | O15: 933056 | P15: 982440 | Q15: 772486 | R15: 967976 | S15: 978574 | T15: 1040295 | U15: 953430 | V15: 1098150 | W15: 1143380 | X15: 1213860 | Y15: 973912 | Z15: 11442149 | AA15: 10441862

Sheet Hyderabad
A1: Particulars | B1: Jan Budget | C1: Jan Actual | D1: Feb Budget | E1: Feb Actual | F1: Mar Budget | G1: Mar Actual | H1: Apr Budget | I1: Apr Actual | J1: May Budget | K1: May Actual | L1: Jun Budget | M1: Jun Actual | N1: Jul Budget | O1: Jul Actual | P1: Aug Budget | Q1: Aug Actual | R1: Sep Budget | S1: Sep Actual | T1: Oct Budget | U1: Oct Actual | V1: Nov Budget | W1: Nov Actual | X1: Dec Budget | Y1: Dec Actual | Z1: Annual Budget | AA1: Annual Actual
A2: Revenue | B2: 11000000 | C2: 11000000 | D2: 11220000 | E2: 11444400 | F2: 11440000 | G2: 10982400 | H2: 11330000 | I2: 11669900 | J2: 11660000 | K2: 11426800 | L2: 11880000 | M2: 11880000 | N2: 12100000 | O2: 12342000 | P2: 12320000 | Q2: 11827200 | R2: 12210000 | S2: 12576300 | T2: 12760000 | U2: 12760000 | V2: 13200000 | W2: 13728000 | X2: 14080000 | Y2: 13516800 | Z2: 145200000 | AA2: 145153800
A3: COGS | B3: 6600000 | C3: 6655000 | D3: 6732000 | E3: 6923862 | F3: 6864000 | G3: 6644352 | H3: 6798000 | I3: 7060290 | J3: 6996000 | K3: 6913214 | L3: 7128000 | M3: 7187400 | N3: 7260000 | O3: 7466910 | P3: 7392000 | Q3: 7155456 | R3: 7326000 | S3: 7608662 | T3: 7656000 | U3: 7719800 | V3: 7920000 | W3: 8305440 | X3: 8448000 | Y3: 8177664 | Z3: 87120000 | AA3: 87818050
A4: Gross Profit | B4: 4400000 | C4: 4345000 | D4: 4488000 | E4: 4520538 | F4: 4576000 | G4: 4338048 | H4: 4532000 | I4: 4609610 | J4: 4664000 | K4: 4513586 | L4: 4752000 | M4: 4692600 | N4: 4840000 | O4: 4875090 | P4: 4928000 | Q4: 4671744 | R4: 4884000 | S4: 4967638 | T4: 5104000 | U4: 5040200 | V4: 5280000 | W4: 5422560 | X4: 5632000 | Y4: 5339136 | Z4: 58080000 | AA4: 57335750
A5: Salaries | B5: 1320000 | C5: 1346400 | D5: 1346400 | E5: 1373328 | F5: 1372800 | G5: 1400256 | H5: 1359600 | I5: 1386792 | J5: 1399200 | K5: 1427184 | L5: 1425600 | M5: 1454112 | N5: 1452000 | O5: 1481040 | P5: 1478400 | Q5: 1507968 | R5: 1465200 | S5: 1494504 | T5: 1531200 | U5: 1561824 | V5: 1584000 | W5: 1615680 | X5: 1689600 | Y5: 1723392 | Z5: 17424000 | AA5: 17772480
A6: Rent | B6: 500000 | C6: 500000 | D6: 500000 | E6: 500000 | F6: 500000 | G6: 500000 | H6: 500000 | I6: 500000 | J6: 500000 | K6: 500000 | L6: 500000 | M6: 500000 | N6: 500000 | O6: 500000 | P6: 500000 | Q6: 500000 | R6: 500000 | S6: 500000 | T6: 500000 | U6: 500000 | V6: 500000 | W6: 500000 | X6: 500000 | Y6: 500000 | Z6: 6000000 | AA6: 6000000
A7: Utilities | B7: 132000 | C7: 135960 | D7: 134640 | E7: 138679 | F7: 137280 | G7: 141398 | H7: 135960 | I7: 140039 | J7: 139920 | K7: 144118 | L7: 142560 | M7: 146837 | N7: 145200 | O7: 149556 | P7: 147840 | Q7: 152275 | R7: 146520 | S7: 150916 | T7: 153120 | U7: 157714 | V7: 158400 | W7: 163152 | X7: 168960 | Y7: 174029 | Z7: 1742400 | AA7: 1794673
A8: Marketing | B8: 440000 | C8: 462000 | D8: 448800 | E8: 471240 | F8: 457600 | G8: 480480 | H8: 453200 | I8: 475860 | J8: 466400 | K8: 489720 | L8: 475200 | M8: 498960 | N8: 484000 | O8: 508200 | P8: 492800 | Q8: 517440 | R8: 488400 | S8: 512820 | T8: 510400 | U8: 535920 | V8: 528000 | W8: 554400 | X8: 563200 | Y8: 591360 | Z8: 5808000 | AA8: 6098400
A9: Other Opex | B9: 275000 | C9: 283250 | D9: 280500 | E9: 288915 | F9: 286000 | G9: 294580 | H9: 283250 | I9: 291748 | J9: 291500 | K9: 300245 | L9: 297000 | M9: 305910 | N9: 302500 | O9: 311575 | P9: 308000 | Q9: 317240 | R9: 305250 | S9: 314408 | T9: 319000 | U9: 328570 | V9: 330000 | W9: 339900 | X9: 352000 | Y9: 362560 | Z9: 3630000 | AA9: 3738901
A10: EBITDA | B10: 1733000 | C10: 1617390 | D10: 1777660 | E10: 1748376 | F10: 1822320 | G10: 1521334 | H10: 1799990 | I10: 1815171 | J10: 1866980 | K10: 1652319 | L10: 1911640 | M10: 1786781 | N10: 1956300 | O10: 1924719 | P10: 2000960 | Q10: 1676821 | R10: 1978630 | S10: 1994990 | T10: 2090280 | U10: 1956172 | V10: 2179600 | W10: 2249428 | X10: 2358240 | Y10: 1987795 | Z10: 23475600 | AA10: 21931296
A11: Depreciation | B11: 250000 | C11: 250000 | D11: 250000 | E11: 250000 | F11: 250000 | G11: 250000 | H11: 250000 | I11: 250000 | J11: 250000 | K11: 250000 | L11: 250000 | M11: 250000 | N11: 250000 | O11: 250000 | P11: 250000 | Q11: 250000 | R11: 250000 | S11: 250000 | T11: 250000 | U11: 250000 | V11: 250000 | W11: 250000 | X11: 250000 | Y11: 250000 | Z11: 3000000 | AA11: 3000000
A12: Interest | B12: 100000 | C12: 100000 | D12: 100000 | E12: 100000 | F12: 100000 | G12: 100000 | H12: 100000 | I12: 100000 | J12: 100000 | K12: 100000 | L12: 100000 | M12: 100000 | N12: 100000 | O12: 100000 | P12: 100000 | Q12: 100000 | R12: 100000 | S12: 100000 | T12: 100000 | U12: 100000 | V12: 100000 | W12: 100000 | X12: 100000 | Y12: 100000 | Z12: 1200000 | AA12: 1200000
A13: Profit Before Tax | B13: 1383000 | C13: 1267390 | D13: 1427660 | E13: 1398376 | F13: 1472320 | G13: 1171334 | H13: 1449990 | I13: 1465171 | J13: 1516980 | K13: 1302319 | L13: 1561640 | M13: 1436781 | N13: 1606300 | O13: 1574719 | P13: 1650960 | Q13: 1326821 | R13: 1628630 | S13: 1644990 | T13: 1740280 | U13: 1606172 | V13: 1829600 | W13: 1899428 | X13: 2008240 | Y13: 1637795 | Z13: 19275600 | AA13: 17731296
... A15: Net Profit | B15: 1037250 | C15: 950542 | D15: 1070745 | E15: 1048782 | F15: 1104240 | G15: 878500 | H15: 1087492 | I15: 1098878 | J15: 1137735 | K15: 976739 | L15: 1171230 | M15: 1077586 | N15: 1204725 | O15: 1181039 | P15: 1238220 | Q15: 995116 | R15: 1221472 | S15: 1233742 | T15: 1305210 | U15: 1204629 | V15: 1372200 | W15: 1424571 | X15: 1506180 | Y15: 1228346 | Z15: 14456699 | AA15: 13298470

Sheet Bangalore
A1: Particulars | B1: Jan Budget | C1: Jan Actual | D1: Feb Budget | E1: Feb Actual | F1: Mar Budget | G1: Mar Actual | H1: Apr Budget | I1: Apr Actual | J1: May Budget | K1: May Actual | L1: Jun Budget | M1: Jun Actual | N1: Jul Budget | O1: Jul Actual | P1: Aug Budget | Q1: Aug Actual | R1: Sep Budget | S1: Sep Actual | T1: Oct Budget | U1: Oct Actual | V1: Nov Budget | W1: Nov Actual | X1: Dec Budget | Y1: Dec Actual | Z1: Annual Budget | AA1: Annual Actual
A2: Revenue | B2: 14500000 | C2: 14500000 | D2: 14790000 | E2: 15085800 | F2: 15080000 | G2: 14476800 | H2: 14935000 | I2: 15383050 | J2: 15370000 | K2: 15062600 | L2: 15660000 | M2: 15660000 | N2: 15950000 | O2: 16269000 | P2: 16240000 | Q2: 15590400 | R2: 16095000 | S2: 16577850 | T2: 16820000 | U2: 16820000 | V2: 17400000 | W2: 18096000 | X2: 18560000 | Y2: 17817600 | Z2: 191400000 | AA2: 191339100
A3: COGS | B3: 8700000 | C3: 8772500 | D3: 8874000 | E3: 9126909 | F3: 9048000 | G3: 8758464 | H3: 8961000 | I3: 9306745 | J3: 9222000 | K3: 9112873 | L3: 9396000 | M3: 9474300 | N3: 9570000 | O3: 9842745 | P3: 9744000 | Q3: 9432192 | R3: 9657000 | S3: 10029599 | T3: 10092000 | U3: 10176100 | V3: 10440000 | W3: 10948080 | X3: 11136000 | Y3: 10779648 | Z3: 114840000 | AA3: 115760155
A4: Gross Profit | B4: 5800000 | C4: 5727500 | D4: 5916000 | E4: 5958891 | F4: 6032000 | G4: 5718336 | H4: 5974000 | I4: 6076305 | J4: 6148000 | K4: 5949727 | L4: 6264000 | M4: 6185700 | N4: 6380000 | O4: 6426255 | P4: 6496000 | Q4: 6158208 | R4: 6438000 | S4: 6548251 | T4: 6728000 | U4: 6643900 | V4: 6960000 | W4: 7147920 | X4: 7424000 | Y4: 7037952 | Z4: 76560000 | AA4: 75578945
A5: Salaries | B5: 1740000 | C5: 1774800 | D5: 1774800 | E5: 1810296 | F5: 1809600 | G5: 1845792 | H5: 1792200 | I5: 1828044 | J5: 1844400 | K5: 1881288 | L5: 1879200 | M5: 1916784 | N5: 1914000 | O5: 1952280 | P5: 1948800 | Q5: 1987776 | R5: 1931400 | S5: 1970028 | T5: 2018400 | U5: 2058768 | V5: 2088000 | W5: 2129760 | X5: 2227200 | Y5: 2271744 | Z5: 22968000 | AA5: 23427360
A6: Rent | B6: 500000 | C6: 500000 | D6: 500000 | E6: 500000 | F6: 500000 | G6: 500000 | H6: 500000 | I6: 500000 | J6: 500000 | K6: 500000 | L6: 500000 | M6: 500000 | N6: 500000 | O6: 500000 | P6: 500000 | Q6: 500000 | R6: 500000 | S6: 500000 | T6: 500000 | U6: 500000 | V6: 500000 | W6: 500000 | X6: 500000 | Y6: 500000 | Z6: 6000000 | AA6: 6000000
A7: Utilities | B7: 174000 | C7: 179220 | D7: 177480 | E7: 182804 | F7: 180960 | G7: 186389 | H7: 179220 | I7: 184597 | J7: 184440 | K7: 189973 | L7: 187920 | M7: 193558 | N7: 191400 | O7: 197142 | P7: 194880 | Q7: 200726 | R7: 193140 | S7: 198934 | T7: 201840 | U7: 207895 | V7: 208800 | W7: 215064 | X7: 222720 | Y7: 229402 | Z7: 2296800 | AA7: 2365704
A8: Marketing | B8: 580000 | C8: 609000 | D8: 591600 | E8: 621180 | F8: 603200 | G8: 633360 | H8: 597400 | I8: 627270 | J8: 614800 | K8: 645540 | L8: 626400 | M8: 657720 | N8: 638000 | O8: 669900 | P8: 649600 | Q8: 682080 | R8: 643800 | S8: 675990 | T8: 672800 | U8: 706440 | V8: 696000 | W8: 730800 | X8: 742400 | Y8: 779520 | Z8: 7656000 | AA8: 8038800
A9: Other Opex | B9: 362500 | C9: 373375 | D9: 369750 | E9: 380842 | F9: 377000 | G9: 388310 | H9: 373375 | I9: 384576 | J9: 384250 | K9: 395778 | L9: 391500 | M9: 403245 | N9: 398750 | O9: 410712 | P9: 406000 | Q9: 418180 | R9: 402375 | S9: 414446 | T9: 420500 | U9: 433115 | V9: 435000 | W9: 448050 | X9: 464000 | Y9: 477920 | Z9: 4785000 | AA9: 4928549
A10: EBITDA | B10: 2443500 | C10: 2291105 | D10: 2502370 | E10: 2463769 | F10: 2561240 | G10: 2164485 | H10: 2531805 | I10: 2551818 | J10: 2620110 | K10: 2337148 | L10: 2678980 | M10: 2514393 | N10: 2737850 | O10: 2696221 | P10: 2796720 | Q10: 2369446 | R10: 2767285 | S10: 2788853 | T10: 2914460 | U10: 2737682 | V10: 3032200 | W10: 3124246 | X10: 3267680 | Y10: 2779366 | Z10: 32854200 | AA10: 30818532
A11: Depreciation | B11: 250000 | C11: 250000 | D11: 250000 | E11: 250000 | F11: 250000 | G11: 250000 | H11: 250000 | I11: 250000 | J11: 250000 | K11: 250000 | L11: 250000 | M11: 250000 | N11: 250000 | O11: 250000 | P11: 250000 | Q11: 250000 | R11: 250000 | S11: 250000 | T11: 250000 | U11: 250000 | V11: 250000 | W11: 250000 | X11: 250000 | Y11: 250000 | Z11: 3000000 | AA11: 3000000
A12: Interest | B12: 100000 | C12: 100000 | D12: 100000 | E12: 100000 | F12: 100000 | G12: 100000 | H12: 100000 | I12: 100000 | J12: 100000 | K12: 100000 | L12: 100000 | M12: 100000 | N12: 100000 | O12: 100000 | P12: 100000 | Q12: 100000 | R12: 100000 | S12: 100000 | T12: 100000 | U12: 100000 | V12: 100000 | W12: 100000 | X12: 100000 | Y12: 100000 | Z12: 1200000 | AA12: 1200000
A13: Profit Before Tax | B13: 2093500 | C13: 1941105 | D13: 2152370 | E13: 2113769 | F13: 2211240 | G13: 1814485 | H13: 2181805 | I13: 2201818 | J13: 2270110 | K13: 1987148 | L13: 2328980 | M13: 2164393 | N13: 2387850 | O13: 2346221 | P13: 2446720 | Q13: 2019446 | R13: 2417285 | S13: 2438853 | T13: 2564460 | U13: 2387682 | V13: 2682200 | W13: 2774246 | X13: 2917680 | Y13: 2429366 | Z13: 28654200 | AA13: 26618532
... A15: Net Profit | B15: 1570125 | C15: 1455829 | D15: 1614278 | E15: 1585327 | F15: 1658430 | G15: 1360864 | H15: 1636354 | I15: 1651364 | J15: 1702582 | K15: 1490361 | L15: 1746735 | M15: 1623295 | N15: 1790888 | O15: 1759666 | P15: 1835040 | Q15: 1514584 | R15: 1812964 | S15: 1829140 | T15: 1923345 | U15: 1790762 | V15: 2011650 | W15: 2080684 | X15: 2188260 | Y15: 1822024 | Z15: 21490651 | AA15: 19963900
